<?xml version="1.0"?>
<robot name="wheelchair-robot-fhws" xmlns:xacro="http://ros.org/wiki/xacro">

  <xacro:property name="PI" value="3.1415926535897931" />

  <xacro:property name="wheel_radius" value="0.1015" />
  <xacro:property name="wheel_width" value="0.08" />

  <material name="yellow"><color rgba="0.2 0.8 0.0 1.0" /></material>
  <material name="black"><color rgba="0.15 0.15 0.15 1.0" /></material>
  <material name="dark_grey"><color rgba="0.2 0.2 0.2 1.0" /></material>
  <material name="light_grey"><color rgba="0.4 0.4 0.4 1.0" /></material>

  <link name="base_link">
    <origin xyz="0 0 0" rpy="0 0 0" />
  </link>

  <joint name="base_joint" type="fixed">
    <origin xyz="0 0 0.07" rpy="0 0 0" /> 
    <parent link="base_link"/>
    <child link="wcr_base_link" /> 
  </joint>

  <link name="wcr_base_link">
    <visual>
      <origin xyz="0 0 0.0785" rpy="1.570796327 0 1.570796327" />
      <geometry>
        <mesh filename="package://simulation-wcr_description/meshes/0001wcr_basis2.stl" scale="0.001 0.001 0.001"/> 
      </geometry>
      <material name="yellow" />
    </visual>
    <collision>
      <origin xyz="0 0 0.0785" rpy="1.570796327 0 1.570796327"/>
      <geometry>
        <mesh filename="package://simulation-wcr_description/meshes/0001wcr_basis2.stl" scale="0.001 0.001 0.001"/>
      </geometry>
    </collision>
    <inertial>
      <!-- Inertia from CAD model, calculated with MeshLab and GNU Octrave from CAD model-->
      <origin xyz="-2.493446e-03 -0.000043e-03 0.813510e-03" rpy="0 0 0"/> 
      <mass value="70.0"/>
      <inertia
        ixx="1.85471945952" ixy="0.00038041141" ixz="0.01920652814"
        iyy="6.16153629309" iyz="0.00000020914"
        izz="7.71937220641"/>
    </inertial>
  </link>

  <joint name="upper_left_wheel_joint" type="continuous">
    <origin xyz="0.455 0.2925 0.03" rpy="0 0 0" /> 
    <parent link="wcr_base_link"/>
    <child link="upper_left_mecanum_wheel" />
    <axis xyz="0 1 0"/>
  </joint>
  
  <link name="upper_left_mecanum_wheel">
    <visual>
      <origin xyz="0 0.04445 0" rpy="0 0 0" />
      <geometry>
        <mesh filename="package://simulation-wcr_description/meshes/0008_in_mk_mecanum_wheel_left_.stl" scale="0.001 0.001 0.001"/> 
      </geometry>
      <material name="light_grey" />
    </visual>
    <collision>
      <origin xyz="0 0.04 0" rpy="${PI/2} 0 0"/>
      <geometry>
        <cylinder radius="${wheel_radius}" length="${wheel_width}"/>
      </geometry>
    </collision>
    <inertial>
      <origin xyz="-0.006413e-03 -0.105013e-03 0.002938e-03" rpy="0 0 0"/>
      <mass value="2.4"/>
      <inertia
        ixx="0.00791233865" ixy="-0.00000011078" ixz="0.00000031823"
        iyy="0.01341098904" iyz="-0.00000023573"
        izz="0.00791282201"/>
    </inertial>
  </link>

  <joint name="lower_left_wheel_joint" type="continuous">
    <origin xyz="-0.455 0.2925 0.03" rpy="0 0 0" /> 
    <parent link="wcr_base_link"/>
    <child link="lower_left_mecanum_wheel" />
    <axis xyz="0 1 0"/>
  </joint>

  <link name="lower_left_mecanum_wheel">
    <visual>
      <origin xyz="0 0.04445 0" rpy="0 0 0" />
      <geometry>
        <mesh filename="package://simulation-wcr_description/meshes/0008_in_mk_mecanum_wheel_right_.stl" scale="0.001 0.001 0.001"/> 
      </geometry>
      <material name="light_grey" />
    </visual>
    <collision>
      <origin xyz="0 0.04 0" rpy="${PI/2} 0 0"/>
      <geometry>
        <cylinder radius="${wheel_radius}" length="${wheel_width}"/>
      </geometry>
    </collision>
    <inertial>
      <origin xyz="-0.001580e-03 0.048159e-03 0.006711e-03" rpy="0 0 0"/>
      <mass value="2.4"/>
      <inertia
        ixx="0.007912678171" ixy="-0.000000288741" ixz="0.000000102023"
        iyy="0.013410661397" iyz="-0.000000054644"
        izz="0.007911896480"/>
    </inertial>
  </link>

  <joint name="upper_right_wheel_joint" type="continuous">
    <origin xyz="0.455 -0.2925 0.03" rpy="0 0 0" /> 
    <parent link="wcr_base_link"/>
    <child link="upper_right_mecanum_wheel" />
    <axis xyz="0 1 0"/>
  </joint>

  <link name="upper_right_mecanum_wheel">
    <visual>
      <origin xyz="0 -0.04445 0" rpy="0 0 0" />
      <geometry>
        <mesh filename="package://simulation-wcr_description/meshes/0008_in_mk_mecanum_wheel_right_.stl" scale="0.001 0.001 0.001"/> 
      </geometry>
      <material name="light_grey" />
    </visual>
    <collision>
      <origin xyz="0 -0.04 0" rpy="${PI/2} 0 0"/>
      <geometry>
        <cylinder radius="${wheel_radius}" length="${wheel_width}"/>
      </geometry>
    </collision>
    <inertial>
      <origin xyz="-0.001580e-03 0.048159e-03 0.006711e-03" rpy="0 0 0"/>
      <mass value="2.4"/>
      <inertia
        ixx="0.007912678171" ixy="-0.000000288741" ixz="0.000000102023"
        iyy="0.013410661397" iyz="-0.000000054644"
        izz="0.007911896480"/>
    </inertial>
  </link>

  <joint name="lower_right_wheel_joint" type="continuous">
    <origin xyz="-0.455 -0.2925 0.03" rpy="0 0 0" /> 
    <parent link="wcr_base_link"/>
    <child link="lower_right_mecanum_wheel" />
    <axis xyz="0 1 0"/>
  </joint>

  <link name="lower_right_mecanum_wheel">
    <visual>
      <origin xyz="0 -0.04445 0" rpy="0 0 0" />
      <geometry>
        <mesh filename="package://simulation-wcr_description/meshes/0008_in_mk_mecanum_wheel_left_.stl" scale="0.001 0.001 0.001"/> 
      </geometry>
      <material name="light_grey" />
    </visual>
    <collision>
      <origin xyz="0 -0.04 0" rpy="${PI/2} 0 0"/>
      <geometry>
        <cylinder radius="${wheel_radius}" length="${wheel_width}"/>
      </geometry>
    </collision>
    <inertial>
      <origin xyz="-0.006413e-03 -0.105013e-03 0.002938e-03" rpy="0 0 0"/>
      <mass value="2.4"/>
      <inertia
        ixx="0.00791233865" ixy="-0.00000011078" ixz="0.00000031823"
        iyy="0.01341098904" iyz="-0.00000023573"
        izz="0.00791282201"/>
    </inertial>
  </link>

</robot>
