<?xml version="1.0"?>
<robot name="wheelchair-robot-fhws" xmlns:xacro="http://ros.org/wiki/xacro">

  <xacro:property name="PI" value="3.1415926535897931" />

  <xacro:property name="wheel_radius" value="0.1015" />
  <xacro:property name="wheel_width" value="0.08" />

  <material name="yellow"><color rgba="0.2 0.8 0.0 1.0" /></material>
  <material name="black"><color rgba="0.15 0.15 0.15 1.0" /></material>
  <material name="dark_grey"><color rgba="0.2 0.2 0.2 1.0" /></material>
  <material name="light_grey"><color rgba="0.4 0.4 0.4 1.0" /></material>

  <link name="base_link">
    <origin xyz="0 0 0" rpy="0 0 0" />
  </link>

  <joint name="base_joint" type="fixed">
    <origin xyz="0 0 0.07" rpy="0 0 0" /> 
    <parent link="base_link"/>
    <child link="wcr_base_link" /> 
  </joint>

  <gazebo reference="base_link">
    <material>Gazebo/Yellow</material>
    <gravity>true</gravity>
  </gazebo>

  <link name="wcr_base_link">
    <visual>
      <origin xyz="0 0 0.0785" rpy="1.570796327 0 1.570796327" />
      <geometry>
        <mesh filename="package://simulation-wcr_description/meshes/0001wcr_basis2.stl" scale="0.001 0.001 0.001"/> 
      </geometry>
      <material name="yellow" />
    </visual>
    <collision>
      <origin xyz="0 0 0.0785" rpy="1.570796327 0 1.570796327"/>
      <geometry>
        <mesh filename="package://simulation-wcr_description/meshes/0001wcr_basis2.stl" scale="0.001 0.001 0.001"/>
      </geometry>
    </collision>
    <inertial>
      <!-- Inertia from CAD model, calculated with MeshLab and GNU Octrave from CAD model-->
      <origin xyz="-2.493446e-03 -0.000043e-03 0.813510e-03" rpy="0 0 0"/> 
      <mass value="70.0"/>
      <inertia
        ixx="1.85471945952" ixy="0.00038041141" ixz="0.01920652814"
        iyy="6.16153629309" iyz="0.00000020914"
        izz="7.71937220641"/>
    </inertial>
  </link>

  <gazebo reference="wcr_base_link">
    <material>Gazebo/Yellow</material>
  </gazebo>

  <joint name="upper_left_wheel_joint" type="continuous">
    <origin xyz="0.455 0.2925 0.03" rpy="0 0 0" /> 
    <parent link="wcr_base_link"/>
    <child link="upper_left_mecanum_wheel" />
    <axis xyz="0 1 0"/>
  </joint>
  
  <link name="upper_left_mecanum_wheel">
    <visual>
      <origin xyz="0 0.04445 0" rpy="0 0 0" />
      <geometry>
        <mesh filename="package://simulation-wcr_description/meshes/0008_in_mk_mecanum_wheel_left_.stl" scale="0.001 0.001 0.001"/> 
      </geometry>
      <material name="light_grey" />
    </visual>
    <collision>
      <origin xyz="0 0.04 0" rpy="${PI/2} 0 0"/>
      <geometry>
        <cylinder radius="${wheel_radius}" length="${wheel_width}"/>
      </geometry>
    </collision>
    <inertial>
      <origin xyz="-0.006413e-03 -0.105013e-03 0.002938e-03" rpy="0 0 0"/>
      <mass value="2.4"/>
      <inertia
        ixx="0.00791233865" ixy="-0.00000011078" ixz="0.00000031823"
        iyy="0.01341098904" iyz="-0.00000023573"
        izz="0.00791282201"/>
    </inertial>
  </link>

  <joint name="lower_left_wheel_joint" type="continuous">
    <origin xyz="-0.455 0.2925 0.03" rpy="0 0 0" /> 
    <parent link="wcr_base_link"/>
    <child link="lower_left_mecanum_wheel" />
    <axis xyz="0 1 0"/>
  </joint>

  <link name="lower_left_mecanum_wheel">
    <visual>
      <origin xyz="0 0.04445 0" rpy="0 0 0" />
      <geometry>
        <mesh filename="package://simulation-wcr_description/meshes/0008_in_mk_mecanum_wheel_right_.stl" scale="0.001 0.001 0.001"/> 
      </geometry>
      <material name="light_grey" />
    </visual>
    <collision>
      <origin xyz="0 0.04 0" rpy="${PI/2} 0 0"/>
      <geometry>
        <cylinder radius="${wheel_radius}" length="${wheel_width}"/>
      </geometry>
    </collision>
    <inertial>
      <origin xyz="-0.001580e-03 0.048159e-03 0.006711e-03" rpy="0 0 0"/>
      <mass value="2.4"/>
      <inertia
        ixx="0.007912678171" ixy="-0.000000288741" ixz="0.000000102023"
        iyy="0.013410661397" iyz="-0.000000054644"
        izz="0.007911896480"/>
    </inertial>
  </link>

  <joint name="upper_right_wheel_joint" type="continuous">
    <origin xyz="0.455 -0.2925 0.03" rpy="0 0 0" /> 
    <parent link="wcr_base_link"/>
    <child link="upper_right_mecanum_wheel" />
    <axis xyz="0 1 0"/>
  </joint>

  <link name="upper_right_mecanum_wheel">
    <visual>
      <origin xyz="0 -0.04445 0" rpy="0 0 0" />
      <geometry>
        <mesh filename="package://simulation-wcr_description/meshes/0008_in_mk_mecanum_wheel_right_.stl" scale="0.001 0.001 0.001"/> 
      </geometry>
      <material name="light_grey" />
    </visual>
    <collision>
      <origin xyz="0 -0.04 0" rpy="${PI/2} 0 0"/>
      <geometry>
        <cylinder radius="${wheel_radius}" length="${wheel_width}"/>
      </geometry>
    </collision>
    <inertial>
      <origin xyz="-0.001580e-03 0.048159e-03 0.006711e-03" rpy="0 0 0"/>
      <mass value="2.4"/>
      <inertia
        ixx="0.007912678171" ixy="-0.000000288741" ixz="0.000000102023"
        iyy="0.013410661397" iyz="-0.000000054644"
        izz="0.007911896480"/>
    </inertial>
  </link>

  <joint name="lower_right_wheel_joint" type="continuous">
    <origin xyz="-0.455 -0.2925 0.03" rpy="0 0 0" /> 
    <parent link="wcr_base_link"/>
    <child link="lower_right_mecanum_wheel" />
    <axis xyz="0 1 0"/>
  </joint>

  <link name="lower_right_mecanum_wheel">
    <visual>
      <origin xyz="0 -0.04445 0" rpy="0 0 0" />
      <geometry>
        <mesh filename="package://simulation-wcr_description/meshes/0008_in_mk_mecanum_wheel_left_.stl" scale="0.001 0.001 0.001"/> 
      </geometry>
      <material name="light_grey" />
    </visual>
    <collision>
      <origin xyz="0 -0.04 0" rpy="${PI/2} 0 0"/>
      <geometry>
        <cylinder radius="${wheel_radius}" length="${wheel_width}"/>
      </geometry>
    </collision>
    <inertial>
      <origin xyz="-0.006413e-03 -0.105013e-03 0.002938e-03" rpy="0 0 0"/>
      <mass value="2.4"/>
      <inertia
        ixx="0.00791233865" ixy="-0.00000011078" ixz="0.00000031823"
        iyy="0.01341098904" iyz="-0.00000023573"
        izz="0.00791282201"/>
    </inertial>
  </link>

  <gazebo reference="upper_left_mecanum_wheel">
    <material>Gazebo/Grey</material>
  </gazebo>

  <gazebo reference="lower_left_mecanum_wheel">
    <material>Gazebo/DarkGrey</material>
  </gazebo>

  <gazebo reference="upper_right_mecanum_wheel">
    <material>Gazebo/DarkGrey</material>
  </gazebo>

  <gazebo reference="lower_right_mecanum_wheel">
    <material>Gazebo/Grey</material>
  </gazebo>

  <joint name="lidar_joint" type="fixed">
    <origin xyz="0.535 0.2875 0.1838" rpy="0 0 0" /> 
    <parent link="wcr_base_link"/>
    <child link="lidar" /> 
  </joint>

  <link name="lidar">
    <visual>
      <origin xyz="0 0 -0.0308" rpy="0 0 0" />
      <geometry>
        <mesh filename="package://simulation-wcr_description/meshes/rplidar-a2m4-r1.stl" scale="0.001 0.001 0.001"/> 
      </geometry>
      <material name="black" />
    </visual>
    <collision>
      <origin xyz="0 0 -0.0104" rpy="0 0 0"/>
      <geometry>
        <cylinder radius="0.045" length="0.05"/>
      </geometry>
    </collision>
    <inertial>
      <origin xyz="0 0 0" rpy="0 0 0"/>
      <mass value="0.125"/>
      <inertia
        ixx="0.001" ixy="0.0000" ixz="0.00000"
        iyy="0.001" iyz="0.000"
        izz="0.001"/>
    </inertial>
  </link>

  <gazebo reference="lidar">
    <sensor type="ray" name="RPLiDAR_A2M8">
      <pose>0 0 0 0 0 0</pose>
      <always_on>true</always_on>
      <visualize>false</visualize>
      <update_rate>100</update_rate>
      <ray>
        <scan>
          <horizontal>
            <samples>400</samples>
            <resolution>1</resolution>
            <min_angle>0.0</min_angle>
            <max_angle>6.28319</max_angle>
          </horizontal>
        </scan>
        <range>
          <min>0.15</min>
          <max>8.0</max>
          <resolution>0.08</resolution>
        </range>
        <noise>
          <type>gaussian</type>
          <mean>0.0</mean>
          <stddev>0.015</stddev> <!--stddev needs to be checked again-->
        </noise>
      </ray>
      <plugin name="RPLiDAR_A2M8_measurement" filename="libgazebo_ros_laser.so">
        <topicName>/lidar_scan</topicName>
        <frameName>RPLiDAR</frameName>
      </plugin>
    </sensor>
  </gazebo>

  <gazebo reference="lidar">
    <material>Gazebo/Black</material>
  </gazebo>

  <!-- Linking Gazebo and ROS-->
  <gazebo>
    <plugin name="gazebo_ros_control" filename="libgazebo_ros_control.so">
      <robotNamespace>/</robotNamespace>
    </plugin>
  </gazebo>
  <!--Including planar movement in order to imitate omidirectional movement with mecanum wheels-->
  <gazebo>
    <plugin name="object_controller" filename="libgazebo_ros_planar_move.so">
      <commandTopic>cmd_vel</commandTopic>
      <odometryTopic>odom</odometryTopic>
      <odometryFrame>odom</odometryFrame>
      <odometryRate>20.0</odometryRate>
      <robotBaseFrame>base_link</robotBaseFrame>
      <cmdTimeout>1.0</cmdTimeout>
    </plugin>
  </gazebo>

  <!-- This block connects joints to actuator (dc motors), which informs both
  simulation and visualization of the robot. Only used for showing model right in RViZ.-->
  <transmission name="left_front_wheel">
    <type>transmission_interface/SimpleTransmission</type>
    <actuator name="$left_front_dc_motor">
      <mechanicalReduction>1</mechanicalReduction>
    </actuator>
    <joint name="upper_left_wheel_joint">
      <hardwareInterface>hardware_interface/PositionJointInterface</hardwareInterface>
    </joint>
  </transmission>  

  <transmission name="left_back_wheel">
    <type>transmission_interface/SimpleTransmission</type>
    <actuator name="$left_back_dc_motor">
      <mechanicalReduction>1</mechanicalReduction>
    </actuator>
    <joint name="lower_left_wheel_joint">
      <hardwareInterface>hardware_interface/PositionJointInterface</hardwareInterface>
    </joint>
  </transmission>  

  <transmission name="right_front_wheel">
    <type>transmission_interface/SimpleTransmission</type>
    <actuator name="$right_front_dc_motor">
      <mechanicalReduction>1</mechanicalReduction>
    </actuator>
    <joint name="upper_right_wheel_joint">
      <hardwareInterface>hardware_interface/PositionJointInterface</hardwareInterface>
    </joint>
  </transmission>  

  <transmission name="right_back_wheel">
    <type>transmission_interface/SimpleTransmission</type>
    <actuator name="$right_back_dc_motor">
      <mechanicalReduction>1</mechanicalReduction>
    </actuator>
    <joint name="lower_right_wheel_joint">
      <hardwareInterface>hardware_interface/PositionJointInterface</hardwareInterface>
    </joint>
  </transmission>  

</robot>
